Workbook
Name A: #REF!
Name acum: #REF!
Name acum: #REF!
Name acum: #REF!
Name COM_INTERCOMPANY: 'Resultado Intercompany'!$B$1:$C$21
Name Copia: #REF!
Name Copia: #REF!
Name Copia: #REF!
Name d: #REF!
Name d: #REF!
Name d: #REF!
Name dez: #REF!
Name dez: #REF!
Name dez: #REF!
Name miguel: #REF!
Name miguel: #REF!
Name miguel: #REF!
Name NÍVEL: [1]Plan1!$E$1:$E$65536
Name nov: #REF!
Name nov: #REF!
Name nov: #REF!
Name O: #REF!
Name OUT: #REF!
Name OUT: #REF!
Name OUT: #REF!
Name RECEITA: #REF!
Name RECEITA: #REF!
Name RECEITA: #REF!
Name sim: #REF!
Name sim: #REF!
Name sim: #REF!
Name trim: #REF!
Name trim: #REF!
Name trim: #REF!
Name VALORES: [1]Plan1!$BY$1:$BY$65536

Sheet Passo a Passo
A1: Cotas | C1: TOTAIS 20 E 21 | E1: DRE 2025 | G1: Resumo DRE 2 BACKUP
A2: BRUNO | C2: Nada a fazer, está automático | E2: Está automático, alterar somente no início do ano | G2: Não alterar. Devo tirar
A5: Pessoas | C5: Honorários | E5: Resultado Orçado | G5: Resumo DRE Outros 2
A6: BRUNO | C6: Nada a fazer, está automático | E6: Está automático, alterar somente no início do ano | G6: Não alterar. Devo tirar
A9: DRE | C9: GLOSAS | E9: OKR
A10: A planilha do DRE é enviada por e-mail | C10: Nada a fazer, está automático | E10: Está automático, alterar somente no início do ano
A11: Excluir linhas em branco e que não são necessárias da planilha DRE
A12: Linhas 29, 50, 51, 55, 56, 59, 60 e 63 em diante
C13: Impostos | E13: Projeção 2025
A14: Copiar a coluna do mês da planilha DRE e copiar valores no mês do Informações Gerenciais | C14: Nada a fazer, está automático | E14: Está automático, alterar somente no início do ano
A15: Copiar a coluna de % do mês anterior e copiar na coluna % do mês corrente
A17: Coluna Evolução (AW): ajustar a célula AW3 para o mês corrente/mês anterior | C17: Resultado Intercompany | E17: Resumo DRE 2
A18: Copiar para todas as células abaixo (até a linha 48) e apagar os que derem erro | C18: Somente simulação | E18: Copiar do mês anterior, colar no final e trocar o mês para o mês atual
C21: Crescimento | E21: Resumo DRE 2 Outros
C22: Nada a fazer, está automático | E22: Copiar do mês anterior, colar no final e trocar o mês para o mês atual
C25: Aux Antecipação
C26: Nada a fazer, está automático
C29: Antecipação Consolidado
C30: Nada a fazer, está automático
C33: Antecipação Lucros GAN
C34: Nada a fazer, está automático
C37: Antecipação Lucros GAA
C38: Nada a fazer, está automático
C41: Antecipação Lucros GAA
C42: Nada a fazer, está automático

Sheet TOTAIS  20 E 21
A1: Mês | B1: 43101 | C1: 43132 | D1: 43160 | E1: 43191 | F1: 43221 | G1: 43252 | H1: 43282 | I1: 43313 | J1: 43344 | K1: 43374 | L1: 43405 | M1: 43435 | N1: 43466 | O1: 43497 | P1: 43525 | Q1: 43556 | R1: 43586 | S1: 43617 | T1: 43647 | U1: 43678 | V1: 43709 | W1: 43739 | X1: 43770 | Y1: 43800 | Z1: 43831 | AA1: 43862 | AB1: 43891 | AC1: 43922 | AD1: 43952 | AE1: 43983 | AF1: 44013 | AG1: 44044 | AH1: 44075 | AI1: 44105 | AJ1: 44136 | AK1: 44166 | AL1: 44197 | AM1: 44228 | AN1: 44256 | AO1: 44287 | AP1: 44317 | AQ1: 44348 | AR1: 44378 | AS1: 44409 | AT1: 44440 | AU1: 44470 | AV1: 44501 | AW1: 44531 | AX1: 44562 | AY1: 44593 | AZ1: 44621 | BA1: 44652 | BB1: 44682 | BC1: 44713 | BD1: 44743 | BE1: 44774 | BF1: 44805 | BG1: 44835 | BH1: 44866 | BI1: 44896 | BJ1: 44927 | BK1: 44958 | BL1: 44986 | BM1: 45017 | BN1: 45047 | BO1: 45078 | BP1: 45108 | BQ1: 45139 | BR1: 45170 | BS1: 45200 | BT1: 45231 | BU1: 45261 | BV1: 45292 | BW1: 45323 | BX1: 45352 | BY1: 45383 | BZ1: 45413 | CA1: 45444 | CB1: 45474 | CC1: 45505 | CD1: 45536 | CE1: 45566 | CF1: 45597 | CG1: 45627 | CH1: 45658 | CI1: 45689 | CJ1: 45717 | CK1: 45748 | CL1: 45778 | CM1: 45809 | CN1: 45839 | CO1: 45870 | CP1: 45901 | CQ1: 45931 | CR1: 45962 | CS1: 45992 | CT1: 46023 | CU1: 46054 | CV1: 46082 | CW1: 46113 | CX1: 46143 | CY1: 46174 | CZ1: 46204 | DA1: 46235 | DB1: 46266 | DC1: 46296 | DD1: 46327 | DE1: 46357
A2: RECEITA | B2: 1307223.8 | C2: 1533151.6 | D2: 990409.83 | E2: 1675538.8 | F2: 1390304.1 | G2: 1429726.9 | H2: 1617844.9 | I2: 1754379.8 | J2: 1464234.7 | K2: 2097191.6 | L2: 1576315.3 | M2: 1978552.7 | N2: 1467400.1 | O2: 1032717.8 | P2: 1313738 | Q2: 1330213.9 | R2: 1973924 | S2: 2136174.2 | T2: 1983098.6 | U2: 2276787.9 | V2: 1849436 | W2: 1853373.7 | X2: 2489722.6 | Y2: 1833456.7 | Z2: 2128952.8 | AA2: 1573272.1 | AB2: 2476961.4 | AC2: 2086485.9 | AD2: 2038109.1 | AE2: 1960087.8 | AF2: 2449578.4 | AG2: 1751404.7 | AH2: 2636104.9 | AI2: 1991057.4 | AJ2: 2890477.2 | AK2: 2672542.4 | AL2: 2160275.2 | AM2: 1729170.6 | AN2: 1408118.2 | AO2: 2194304.1 | AP2: 2650378.8 | AQ2: 2209415.5 | AR2: 2332555.9 | AS2: 2180870.1 | AT2: 2274247.4 | AU2: 2588760.7 | AV2: 2581281.1 | AW2: 3002777.1 | AX2: 2236775.4 | AY2: 1432655.2 | AZ2: 2011358.9 | BA2: 2659031 | BB2: 3006579.8 | BC2: 2464901.4 | BD2: 2501382.1 | BE2: 2204860 | BF2: 2556896 | BG2: 2707697.4 | BH2: 2415882.5 | BI2: 2692784.6 | BJ2: 2859585.3 | BK2: 2290503.6 | BL2: 2258763.8 | BM2: 3226365.2 | BN2: 2759630.7 | BO2: 2764496.3 | BP2: 2839189 | BQ2: 3801574.8 | BR2: 3346794.8 | BS2: 3245706.1 | BT2: 3479448.7 | BU2: 4923248.9 | BV2: 3209755.3 | BW2: 3256937.7 | BX2: 2605192.5 | BY2: 3293581.6 | BZ2: 3629988.7 | CA2: 4068124.1 | CB2: 4640246.4 | CC2: 3454210 | CD2: 4253136.9 | CE2: 4658140.7 | CF2: 6144339 | CG2: 5312105.9 | CH2: 4402653.9 | CI2: 4086254.3 | CJ2: 4048194.3 | CK2: 3939627.5 | CL2: 3548210.9 | CM2: 4304516.3 | CN2: 4526009.4 | CO2: 4828600.7 | CP2: 4420476.6 | CQ2: 4300330.3 | CR2: 4681796.7 | CS2: 7347433 | CT2: =[2]Resumo!B15 -> 3839058 | CU2: =[2]Resumo!C15 -> 3623744.1 | CV2: =[2]Resumo!D15 -> 4695972.1 | CW2: =[2]Resumo!E15 -> 0 | CX2: =[2]Resumo!F15 -> 0 | CY2: =[2]Resumo!G15 -> 0 | CZ2: =[2]Resumo!H15 -> 0 | DA2: =[2]Resumo!I15 -> 0 | ... DE2: =[2]Resumo!M15 -> 0
A3: DESPESAS DIRETAS | B3: 708765.42 | C3: 634595.95 | D3: 662041.81 | E3: 742911.37 | F3: 759469.18 | G3: 777423.25 | H3: 883382.09 | I3: 891520.17 | J3: 900333.46 | K3: 920790.36 | L3: 920494.07 | M3: 930857.65 | N3: 890181.42 | O3: 829951.36 | P3: 820806.1 | Q3: 902503.24 | R3: 982451.85 | S3: 1040351.8 | T3: 1001203.4 | U3: 946275.41 | V3: 968576.62 | W3: 969050.69 | X3: 1056477.2 | Y3: 1041487.4 | Z3: 1039086.5 | AA3: 938429.41 | AB3: 899844.27 | AC3: 963963.86 | AD3: 900554.9 | AE3: 793490.17 | AF3: 808317.45 | AG3: 809656.85 | AH3: 772069.07 | AI3: 892189.83 | AJ3: 924546.81 | AK3: 1393054.9 | AL3: 415285.19 | AM3: 821040.81 | AN3: 840932.52 | AO3: 860631.29 | AP3: 898437.04 | AQ3: 925258.58 | AR3: 1001705 | AS3: 1096711.4 | AT3: 1082372 | AU3: 1112579.8 | AV3: 1184774.8 | AW3: 1219497.1 | AX3: 1114140.1 | AY3: 1090075.3 | AZ3: 1101136.5 | BA3: 1153879.6 | BB3: 1153290.8 | BC3: 1120894.3 | BD3: 1175595.8 | BE3: 1147607.9 | BF3: 1118378.4 | BG3: 1219122.6 | BH3: 1265784.8 | BI3: 1486797.5 | BJ3: 1307199.6 | BK3: 1215843.7 | BL3: 1332484.4 | BM3: 1366011 | BN3: 1464995.9 | BO3: 1497743 | BP3: 1504470.8 | BQ3: 1468213.9 | BR3: 1440400.7 | BS3: 1575549.3 | BT3: 1585489.8 | BU3: 1644131.1 | BV3: 1553728.7 | BW3: 1501690 | BX3: 1464061.7 | BY3: 1614515.8 | BZ3: 1686791.7 | CA3: 1669217.5 | CB3: 1801187 | CC3: 1746801.2 | CD3: 1790384.3 | CE3: 1949759.5 | CF3: 1962547.7 | CG3: 1933941.4 | CH3: 1870683.4 | CI3: 1806440.4 | CJ3: 1790545.5 | CK3: 1972373.8 | CL3: 1946905.7 | CM3: 2090154.5 | CN3: 2029865.2 | CO3: 1992411.5 | CP3: 2322824.3 | CQ3: 2015292.8 | CR3: 2207852.6 | CS3: 2336604.6 | CT3: =[2]Resumo!B4 -> 2155945.7 | CU3: =[2]Resumo!C4 -> 2075571.3 | CV3: =[2]Resumo!D4 -> 2061591.4 | CW3: =[2]Resumo!E4 -> 0 | CX3: =[2]Resumo!F4 -> 0 | CY3: =[2]Resumo!G4 -> 0 | CZ3: =[2]Resumo!H4 -> 0 | DA3: =[2]Resumo!I4 -> 0 | ... DE3: =[2]Resumo!M4 -> 0
A4: RATEIO | B4: 332194.72 | C4: 293454.54 | D4: 325566.3 | E4: 330675.78 | F4: 330206.32 | G4: 332778.34 | H4: 366709.99 | I4: 356096.92 | J4: 350277.46 | K4: 419661.83 | L4: 419150.69 | M4: 387617.05 | N4: 335686.65 | O4: 389728.84 | P4: 361294.86 | Q4: 340054.08 | R4: 395127.24 | S4: 369936.62 | T4: 391682.35 | U4: 352480.19 | V4: 373168.78 | W4: 389476.32 | X4: 421483.83 | Y4: 362754.21 | Z4: 361623.24 | AA4: 376692.69 | AB4: 367446.84 | AC4: 339909.64 | AD4: 306880.81 | AE4: 354039 | AF4: 346357.49 | AG4: 365009.91 | AH4: 298807.21 | AI4: 365121.2 | AJ4: 430185.28 | AK4: 398005.1 | AL4: 319539.55 | AM4: 348986.27 | AN4: 435814.08 | AO4: 468530.36 | AP4: 405485.03 | AQ4: 382632.07 | AR4: 388403.94 | AS4: 433471.59 | AT4: 380178.73 | AU4: 394002.7 | AV4: 461423.25 | AW4: 520471.7 | AX4: =[3]Resumo!$B$6 -> 411197.23 | AY4: 370795.09 | AZ4: 482868.54 | BA4: 431323.36 | BB4: =[4]Resumo!F6 -> 410612.91 | BC4: =[4]Resumo!G6 -> 438065.66 | BD4: 495251.26 | BE4: 457057.15 | BF4: 482871.9 | BG4: 488973.14 | BH4: 520395.27 | BI4: 535746.53 | BJ4: 525614.49 | BK4: 728482.32 | BL4: 664470.47 | BM4: 572589.57 | BN4: 606099.92 | BO4: 582232.94 | BP4: 516776.07 | BQ4: 580786.49 | BR4: 681582.65 | BS4: 782798.52 | BT4: 626646.6 | BU4: 985291.68 | BV4: 627328.59 | BW4: 518616.76 | BX4: 571591.12 | BY4: 623411.41 | BZ4: 560543.91 | CA4: 596168.44 | CB4: 608089.79 | CC4: 591644.87 | CD4: 597510.21 | CE4: 666795.74 | CF4: 993644.13 | CG4: 1187654.4 | CH4: 522627.38 | CI4: 730178.33 | CJ4: 750656.43 | CK4: 675211.26 | CL4: 780059.86 | CM4: 802238.9 | CN4: 788622.46 | CO4: 738958.34 | CP4: 752322.23 | CQ4: 793137.38 | CR4: 839169.33 | CS4: 909814.03 | CT4: =[2]Resumo!B6 -> 837978.39 | CU4: =[2]Resumo!C6 -> 797117.8 | CV4: =[2]Resumo!D6 -> 1008083.3 | CW4: =[2]Resumo!E6 -> 0 | CX4: =[2]Resumo!F6 -> 0 | CY4: =[2]Resumo!G6 -> 0 | CZ4: =[2]Resumo!H6 -> 0 | DA4: =[2]Resumo!I6 -> 0 | ... DE4: =[2]Resumo!M6 -> 0
A5: IMPOSTOS | B5: 210944.92 | C5: 226407.3 | D5: 195634.8 | E5: 218328.2 | F5: 203735.55 | G5: 196595.38 | H5: 235885.75 | I5: 261422.16 | J5: 239946.41 | K5: 276209.16 | L5: 256866.81 | M5: 314449.01 | N5: 271211.48 | O5: 231422.09 | P5: 260109.57 | Q5: 239030.85 | R5: 232490.53 | S5: 292201.04 | T5: 314124.08 | U5: 314923.33 | V5: 310952.75 | W5: 267928.56 | X5: 343552.54 | Y5: 297743.48 | Z5: 362815.5 | AA5: 302477.74 | AB5: 220426.78 | AC5: 124999.88 | AD5: 119216.88 | AE5: 125261.23 | AF5: 380329.81 | AG5: 345364.76 | AH5: 394835.44 | AI5: 415158.69 | AJ5: 488420.69 | AK5: 461838.32 | AL5: 405804.91 | AM5: 383117.74 | AN5: 367696.38 | AO5: 321574.66 | AP5: 347745.43 | AQ5: 311827.91 | AR5: 420139.04 | AS5: 417868.74 | AT5: 447683.54 | AU5: 479411.87 | AV5: 476625.54 | AW5: 496429.22 | AX5: =[3]Resumo!$B$10 -> 423761.89 | AY5: 396357.71 | AZ5: 418368.58 | BA5: 425611.61 | BB5: =[4]Resumo!F10 -> 478195.25 | BC5: =[4]Resumo!G10 -> 423247.79 | BD5: 464440.59 | BE5: 445200.58 | BF5: 475341.88 | BG5: 463963.06 | BH5: 467278.49 | BI5: 482432.6 | BJ5: 324082.69 | BK5: 257112.66 | BL5: 304168.46 | BM5: 509520.34 | BN5: 497284.81 | BO5: 471048.18 | BP5: 581694.54 | BQ5: 598087.77 | BR5: 544122.9 | BS5: 631456.76 | BT5: 643026.28 | BU5: 718241.35 | BV5: 680191.5 | BW5: 630667.99 | BX5: 650151.33 | BY5: 552891.73 | BZ5: 576432.91 | CA5: 653479.23 | CB5: 770054.08 | CC5: 694145.02 | CD5: 715390.39 | CE5: 786401.31 | CF5: 854779.57 | CG5: 853342.66 | CH5: 1040647.4 | CI5: 839361.01 | CJ5: 908903.32 | CK5: 774000.14 | CL5: 712671.4 | CM5: 770881.2 | CN5: 877117.36 | CO5: 848538.76 | CP5: 933960.87 | CQ5: 841937.24 | CR5: 1000419.2 | CS5: 1221280.6 | CT5: =[2]Resumo!B10 -> 882839.52 | CU5: =[2]Resumo!C10 -> 795514.76 | CV5: =[2]Resumo!D10 -> 834112.59 | CW5: =[2]Resumo!E10 -> 0 | CX5: =[2]Resumo!F10 -> 0 | CY5: =[2]Resumo!G10 -> 0 | CZ5: =[2]Resumo!H10 -> 0 | DA5: =[2]Resumo!I10 -> 0 | ... DE5: =[2]Resumo!M10 -> 0
A6: EBITDA CONTÁBIL | N6: 195555.99 | O6: -163955.75 | P6: 108080.72 | Q6: 52222.846 | R6: 596502.3 | S6: 688988.91 | T6: 557484.98 | U6: 941952.45 | V6: 539912.2 | W6: 527099.02 | X6: 1043822.3 | Y6: 460837.31 | Z6: 752279.52 | AA6: 288094.68 | AB6: 1231684.4 | AC6: 809596.06 | AD6: 843158.53 | AE6: 824281.16 | AF6: 1307004 | AG6: 588323.81 | AH6: 1568343.8 | AI6: 749082.05 | AJ6: 1548171.5 | AK6: 884123.16 | AL6: 1427584.3 | AM6: 564742.87 | AN6: 168689.34 | AO6: 904350.76 | AP6: 1383868.9 | AQ6: 922214.51 | AR6: 955331.41 | AS6: 672459.22 | AT6: 830475.83 | AU6: 1088586 | AV6: 959424.3 | AW6: 1273180.1 | AX6: 720354.63 | AY6: -20420.79 | AZ6: 457895.25 | BA6: 1088552.5 | BB6: 1450341.9 | BC6: 907886.58 | BD6: 836100.1 | BE6: 608298.97 | BF6: 967265.53 | BG6: 1036299.7 | BH6: 677927.71 | BI6: 724723.27 | BJ6: 2192974.6 | BK6: 1490674 | BL6: 1460217.5 | BM6: 2480554.9 | BN6: 1911789.8 | BO6: 1874919.7 | BP6: 2056242.9 | BQ6: 3003304.4 | BR6: 2460871.4 | BS6: 2181433.9 | BT6: 2538064.1 | BU6: 3591757.8
A7: EBITDA GERENCIAL | BJ7: 1116308.6 | BK7: 443156.21 | BL7: 361151.55 | BM7: 1391814.3 | BN7: 782545.29 | BO7: 718360.32 | BP7: 868397.64 | BQ7: 1799057 | BR7: 1271487.7 | BS7: 929643.29 | BT7: 1303758.4 | BU7: 2339803.9 | BV7: - | BW7: - | BX7: - | BY7: - | BZ7: 1263545.8 | CA7: 1696832.8 | CB7: 2062867 | CC7: 1002841.3 | CD7: 1696216.2 | CE7: 1843459.1 | CF7: 3303573.9 | CG7: 2515839.4 | CH7: 1786081.1 | CI7: 1801912.2 | CJ7: 1734464.9 | CK7: 1402504.9 | CL7: 914588.29 | CM7: 1614308 | CT7: =IF(DRE!AX36="","",DRE!AX36) | CU7: =IF(DRE!AY36="","",DRE!AY36) | CV7: =IF(DRE!AZ36="","",DRE!AZ36) | CW7: =IF(DRE!BA36="","",DRE!BA36) | CX7: =IF(DRE!BB36="","",DRE!BB36) | CY7: =IF(DRE!BC36="","",DRE!BC36) | CZ7: =IF(DRE!BD36="","",DRE!BD36) | DA7: =IF(DRE!BE36="","",DRE!BE36) | ... DE7: =IF(DRE!BI36="","",DRE!BI36)
A8: CUSTOS E DESPESAS | B8: =B3+B4+B5 -> 1251905.1 | C8: =C3+C4+C5 -> 1154457.8 | D8: =D3+D4+D5 -> 1183242.9 | E8: =E3+E4+E5 -> 1291915.3 | F8: =F3+F4+F5 -> 1293411 | G8: =G3+G4+G5 -> 1306797 | H8: =H3+H4+H5 -> 1485977.8 | I8: =I3+I4+I5 -> 1509039.3 | ... BI8: =BI3+BI4+BI5 -> 2504976.7 | BJ8: 2156896.8 | BK8: 2201438.7 | BL8: 2301123.3 | BM8: 2448120.9 | BN8: 2568380.6 | BO8: 2551024.1 | BP8: 2602941.4 | BQ8: 2647088.2 | BR8: 2666106.3 | BS8: 2989804.6 | BT8: 2855162.7 | BU8: 3347664.1 | BV8: 2861248.8 | BW8: 2650974.7 | BX8: 2685804.2 | BY8: 2790818.9 | BZ8: 2823768.5 | CA8: 2918865.1 | CB8: 3179330.9 | CC8: 3032591.1 | CD8: 3103284.9 | CE8: 3402956.6 | CF8: 3810971.4 | CG8: 3974938.4 | CH8: 3433958.2 | CI8: 3375979.7 | CJ8: 3450105.3 | CK8: 3421585.2 | CL8: 3439636.9 | CM8: 3663274.6 | CN8: 3695605.1 | CO8: 3579908.6 | CP8: 4009107.4 | CQ8: 3650367.4 | CR8: 4047441.1 | CS8: 4467699.2 | CT8: =IFERROR(CT3+CT4+CT5,"") -> 3876763.6 | CU8: =IFERROR(CU3+CU4+CU5,"") -> 3668203.8 | CV8: =IFERROR(CV3+CV4+CV5,"") -> 3903787.4 | CW8: =IFERROR(CW3+CW4+CW5,"") -> 0 | CX8: =IFERROR(CX3+CX4+CX5,"") -> 0 | CY8: =IFERROR(CY3+CY4+CY5,"") -> 0 | CZ8: =IFERROR(CZ3+CZ4+CZ5,"") -> 0 | DA8: =IFERROR(DA3+DA4+DA5,"") -> 0 | ... DE8: =IFERROR(DE3+DE4+DE5,"") -> 0
A9: RESULTADO IG | B9: =B2-B8 -> 55318.732 | C9: =C2-C8 -> 378693.83 | D9: =D2-D8 -> -192833.08 | E9: =E2-E8 -> 383623.47 | F9: =F2-F8 -> 96893.083 | G9: =G2-G8 -> 122929.91 | H9: =H2-H8 -> 131867.03 | I9: =I2-I8 -> 245340.54 | ... BI9: =BI2-BI8 -> 187807.98 | BJ9: 702688.5 | BK9: 89064.961 | BL9: -42359.506 | BM9: 778244.29 | BN9: 191250.14 | BO9: 213472.21 | BP9: 236247.6 | BQ9: 1154486.7 | BR9: 680688.55 | BS9: 255901.55 | BT9: 624285.97 | BU9: 1575584.8 | BV9: 348506.47 | BW9: 605962.94 | BX9: -80611.71 | BY9: 502762.71 | BZ9: 806220.24 | CA9: 1149259 | CB9: 1460915.5 | CC9: 421618.87 | CD9: 1149852 | CE9: 1255184.1 | CF9: 2333367.6 | CG9: 1337167.5 | CH9: 968695.78 | CI9: 710274.57 | CJ9: 598089.08 | CK9: 518042.31 | CL9: 108573.95 | CM9: 641241.7 | CN9: 830404.33 | CO9: 1248692.2 | CP9: 411369.25 | CQ9: 649962.84 | CR9: 634355.57 | CS9: 2879733.8 | CT9: =IFERROR(CT2-CT8,"") -> -37705.652 | CU9: =IFERROR(CU2-CU8,"") -> -44459.741 | CV9: =IFERROR(CV2-CV8,"") -> 792184.77 | CW9: =IFERROR(CW2-CW8,"") -> 0 | CX9: =IFERROR(CX2-CX8,"") -> 0 | CY9: =IFERROR(CY2-CY8,"") -> 0 | CZ9: =IFERROR(CZ2-CZ8,"") -> 0 | DA9: =IFERROR(DA2-DA8,"") -> 0 | ... DE9: =IFERROR(DE2-DE8,"") -> 0
A10: OBS Receita | BJ10: ANOMALIAS A MAIOR - 530k Mercado Livre - 230k Santander - 200k UOL - 100k | BK10: ANOMALIAS A MAIOR - 210k Intercompany - 210k | BL10: ANOMALIAS A MAIOR - 80k Intercompany - 80k | BM10: ANOMALIAS A MAIOR - 255k ENEL-SP 175k Intercompany - 80k | BN10: ANOMALIAS A MAIOR - 80k Itercompany - 80k ANOMALIAS A MENOR - 175k ENEL-SP 175k | BO10: ANOMALIAS A MAIOR - 80k Intercompany - 80k ANOMALIAS A MENOR Leader - Receita represada Naturgy - Receita represada | BS10: ANOMALIAS A MAIOR - 170k Intercompany - 170k (entra em receitas e sai em despesas) | BU10: ANOMALIAS A MAIOR - 1,7 M Antecipação de notas da Vivo (jan e fev de 2024) - 600k Recebimento de notas atrasadas da BRK - 400k Intercompany - 400k (entra em receitas e sai em despesas) Sucumbências - 300k | BW10: ANOMALIAS A MAIOR - 600k Antecipação de receita de cliente - 600k | CA10: 1. Tivemos (+) 1 milhão no Itaú, recuperação de receita - Parabéns! 2. Não tivemos Vivo (-) 300k - antecipação feita 3. Não tivemos Mercado Livre - prazo alterado (-) 600k Total (+) 100k | CB10: 1. Sucumbências aumentaram em (+) 410k 2. Mercado Livre (+) 500k - antecipamos para gestão de caixa 3. Santander (+) 100k Total (+) 1.000k | CC10: 1. Mercado Livre (-) 600k - não tivemos pois antecipamos em julho Total (-) 600k | CD10: 1. Sucumbências (+) 300k 2. UOL/Estratégico (+) 100k 3. MRS (+) 100k Total (+) 500k Saneamento - Pendência no faturamento de (+) 600k Deve ser liberado em novembro | CF10: 1. Recebimento do atrasado Saneamento 900k 2- Enel SP recebemos esse mês o referente ao mês passado 170k 3. Santander a maior 300k 4. Intercompany 400k Total a maior 1770k Tenho um entendimento que o nosso novo volume de faturamento monta em 4,2MM | CL10: 1- Receita represada de clientes: 450k 2- Sazonalidade MeLi: Jan: recebe em maio / Prazo 90 dias A menor em torno de 300k 3- Cliente com redução de honorário por negociação em contrato: 150k Com esses eventos, a receita seria no mínimo: 4.498k (3748k + 750k)
A11: OBS Custos | BJ11: ANOMALIAS A MENOR - 180k Impostos - 180k | BK11: ANOMALIAS A MAIOR - 210K Intercompany - 210k ANOMALIAS A MENOR - 180k Impostos - 180k | BL11: ANOMALIAS A MAIOR - 80K Intercompany - 80k ANOMALIAS A MENOR - 180k Impostos - 180k | BM11: ANOMALIAS A MAIOR - 324k Impostos - 180k Intercompany - 80k Correspondentes - 50k Vivo - 14k ANOMALIAS A MENOR - 69k Processos Trabalhistas - 69k | BN11: ANOMALIAS A MAIOR - 279k Pessoal - Vivo - 83k Intercompany - 80k Correspondentes - 70k Glosas - 30k Dep recursal - 16k | BO11: ANOMALIAS A MAIOR - 305k Condenações e Depósitos Recursais - Trabalhista - 130K Pessoal - Vivo - 95k Intercompany - 80k | BP11: ANOMALIAS A MAIOR - 100k Processos trabalhistas Rescisão e férias elevados Alguns eventos Festa Soft Line pago em julho ref junho e julho | BS11: ANOMALIAS A MAIOR - 152k Investimento na festa - 70k Imposto ref trimestre anterior a maior - 60k Correspondentes - 22k | BU11: ANOMALIAS A MAIOR - 400k Intercompany - 400k | BW11: ANOMALIAS A MENOR Correspondentes - recesso Intercompany Impostos GAT | BX11: Evolução x 1o Tri 2023 1. Impostos - parte 520k, deixamos de pagar pelo parcelamento 2. Impostos - parte 450k - evolução pelo aumento do faturamento 3. Pessoas - aumento de times - 400k Total 1,4 milhão | CF11: 1. Pagamento 13º Salário 110k 2. Correspondente a maior 50k 3. Intercompany 400k Total a maior 560k Algumas despesas iniciadas para a festa de Final de Ano e Nova Unidade SP
A12: SUCUMBÊNCIA | Z12: 48459.63 | AA12: 15393.73 | AB12: 9094.42 | AC12: 9069.62 | AD12: 14114.65 | AE12: 66299.88 | AF12: 16874.65 | AG12: 22271.86 | AH12: 9498.26 | AI12: 46340.98 | AJ12: 11279 | AK12: 35578.24 | AL12: 11588.99 | AM12: 32223.18 | AN12: 15309.96 | AO12: 45722.61 | AP12: 34502.25 | AQ12: 37779.75 | AR12: 42094.58 | AS12: 45636.69 | AT12: 45175.41 | AU12: 39850.58 | AV12: 83465.23 | AW12: 86874.45 | AX12: 29746.63 | AY12: 18941.76 | AZ12: 32915.16 | BA12: 106067.72 | BB12: 64119.41 | BC12: 111006.47 | BD12: 11551.85 | BE12: 130378.64 | BF12: 66227.94 | BG12: 80018.85 | BH12: 182634.19 | BI12: 133376.75 | BJ12: 17722.4 | BK12: 37863.44 | BL12: 17778.03 | BM12: 37235.69 | BN12: 38944.1 | BO12: 86275.06 | BP12: 171883.22 | BQ12: 77700.86 | BR12: 240605.86 | BS12: 171332.58 | BT12: 165965.22 | BU12: 339598.13 | BV12: =[5]Sucumbências!BD44 -> 45577.95 | BW12: =[5]Sucumbências!BE44 -> 257734.04 | BX12: =[5]Sucumbências!BF44 -> 133547.93 | BY12: =[5]Sucumbências!BG44 -> 39191.42 | BZ12: =[5]Sucumbências!BH44 -> 112128.08 | CA12: =[5]Sucumbências!BI44 -> 187391.46 | CB12: =[5]Sucumbências!BJ44 -> 410618.01 | CC12: =[5]Sucumbências!BK44 -> 303810.37 | ... CG12: =[5]Sucumbências!BO44 -> 889365.66 | CH12: 367038.29 | CI12: 389371.93 | CJ12: 397295.7 | CK12: 321630.05 | CL12: 513933.32 | CM12: 233201.97 | CN12: 112779.26 | CO12: 579410.41 | CP12: 387892.36 | CQ12: 426678.63 | CR12: 247509.19 | CS12: 501699.87 | CT12: =[5]Sucumbências!CD44 -> 430573.42 | CU12: =[5]Sucumbências!CE44 -> 410980.78 | CV12: =[5]Sucumbências!CF44 -> 0 | CW12: =[5]Sucumbências!CG44 -> 0 | CX12: =[5]Sucumbências!CH44 -> 0 | CY12: =[5]Sucumbências!CI44 -> 0 | CZ12: =[5]Sucumbências!CJ44 -> 0 | DA12: =[5]Sucumbências!CK44 -> 0 | ... DE12: =[5]Sucumbências!CO44 -> 0
A13: GLOSAS | Z13: 15818.67 | AA13: 19856.42 | AB13: 27171.63 | AC13: 300 | AD13: 5304.8 | AE13: 1476.66 | AF13: 8208.94 | AG13: 608.23 | AH13: 4276.55 | AI13: 7719.49 | AJ13: 56314.59 | AK13: 11300 | AL13: 0 | AM13: 0 | AN13: 0 | AO13: 3331.13 | AP13: 5311.54 | AQ13: 6512.89 | AR13: 3779.88 | AS13: 35269.8 | AT13: 25874.19 | AU13: 21889.69 | AV13: 25793.59 | AW13: 13816.28 | AX13: 11747.12 | AY13: 5696.73 | AZ13: 5693.35 | BA13: 7446.7 | BB13: 14391.15 | BC13: 14336.19 | BD13: 2040.76 | BE13: 5100.35 | BF13: 6902.78 | BG13: 14970.92 | BH13: 13723.56 | BI13: 176797.66 | BJ13: 17170.8 | BK13: 22510 | BL13: 32443.95 | BM13: 17170.8 | BN13: 28040.83 | BO13: 65037.66 | BP13: 21614.62 | BQ13: 22194.29 | BR13: 23943.87 | BS13: 32073.5 | BT13: 41254.85 | BU13: 32755.25 | BV13: =IF(BV2="","",GLOSAS!BD43) -> 22436.78 | BW13: =IF(BW2="","",GLOSAS!BE43) -> 37827.72 | BX13: =IF(BX2="","",GLOSAS!BF43) -> 13762.51 | BY13: =IF(BY2="","",GLOSAS!BG43) -> 36048.9 | BZ13: =IF(BZ2="","",GLOSAS!BH43) -> 69000.39 | CA13: =IF(CA2="","",GLOSAS!BI43) -> 43713.2 | CB13: =IF(CB2="","",GLOSAS!BJ43) -> 150696.85 | CC13: =IF(CC2="","",GLOSAS!BK43) -> 78157.04 | ... CG13: =IF(CG2="","",GLOSAS!BO43) -> 48676.61 | CH13: 28380.25 | CI13: 46323.67 | CJ13: 30467.12 | CK13: 48258.81 | CL13: -25177.88 | CM13: 141289.77 | CN13: 36171.73 | CO13: 21721.53 | CP13: 252293.12 | CQ13: 31609.76 | CR13: 63494.05 | CS13: 21560.92 | CT13: =IF(CT2="","",GLOSAS!CD43) -> 9114.04 | CU13: =IF(CU2="","",GLOSAS!CE43) -> 23550.57 | CV13: =IF(CV2="","",GLOSAS!CF43) -> 31308.16 | CW13: =IF(CW2="","",GLOSAS!CG43) -> 0 | CX13: =IF(CX2="","",GLOSAS!CH43) -> 0 | CY13: =IF(CY2="","",GLOSAS!CI43) -> 0 | CZ13: =IF(CZ2="","",GLOSAS!CJ43) -> 0 | DA13: =IF(DA2="","",GLOSAS!CK43) -> 0 | ... DE13: =IF(DE2="","",GLOSAS!CO43) -> 0
A14: IMPOSTO SUCUMBÊNCIA | Z14: =IF(Z2="","",Z12*0.1) -> 4845.963 | AA14: =IF(AA2="","",AA12*0.1) -> 1539.373 | AB14: =IF(AB2="","",AB12*0.1) -> 909.442 | AC14: =IF(AC2="","",AC12*0.1) -> 906.962 | AD14: =IF(AD2="","",AD12*0.1) -> 1411.465 | AE14: =IF(AE2="","",AE12*0.1) -> 6629.988 | AF14: =IF(AF2="","",AF12*0.1) -> 1687.465 | AG14: =IF(AG2="","",AG12*0.1) -> 2227.186 | ... CG14: =IF(CG2="","",CG12*0.1) -> 88936.566 | CH14: 36703.829 | CI14: 38937.193 | CJ14: 39729.57 | CK14: 32163.005 | CL14: 51393.332 | CM14: 23320.197 | CN14: 11277.926 | CO14: 57941.041 | CP14: 38789.236 | CQ14: 42667.863 | CR14: 24750.919 | CS14: 50169.987 | CT14: =IF(CT2="","",CT12*0.1) -> 43057.342 | CU14: =IF(CU2="","",CU12*0.1) -> 41098.078 | CV14: =IF(CV2="","",CV12*0.1) -> 0 | CW14: =IF(CW2="","",CW12*0.1) -> 0 | CX14: =IF(CX2="","",CX12*0.1) -> 0 | CY14: =IF(CY2="","",CY12*0.1) -> 0 | CZ14: =IF(CZ2="","",CZ12*0.1) -> 0 | DA14: =IF(DA2="","",DA12*0.1) -> 0 | ... DE14: =IF(DE2="","",DE12*0.1) -> 0
A15: IMPOSTOS SEM SUCUMBÊNCIA | Z15: =IF(Z2="","",Z5-Z14) -> 357969.54 | AA15: =IF(AA2="","",AA5-AA14) -> 300938.36 | AB15: =IF(AB2="","",AB5-AB14) -> 219517.34 | AC15: =IF(AC2="","",AC5-AC14) -> 124092.92 | AD15: =IF(AD2="","",AD5-AD14) -> 117805.42 | AE15: =IF(AE2="","",AE5-AE14) -> 118631.25 | AF15: =IF(AF2="","",AF5-AF14) -> 378642.35 | AG15: =IF(AG2="","",AG5-AG14) -> 343137.57 | ... CG15: =IF(CG2="","",CG5-CG14) -> 764406.09 | CH15: 1003943.6 | CI15: 800423.82 | CJ15: 869173.75 | CK15: 741837.14 | CL15: 661278.07 | CM15: 747561 | CN15: 865839.43 | CO15: 790597.72 | CP15: 895171.63 | CQ15: 799269.38 | CR15: 975668.31 | CS15: 1171110.6 | CT15: =IF(CT2="","",CT5-CT14) -> 839782.18 | CU15: =IF(CU2="","",CU5-CU14) -> 754416.68 | CV15: =IF(CV2="","",CV5-CV14) -> 834112.59 | CW15: =IF(CW2="","",CW5-CW14) -> 0 | CX15: =IF(CX2="","",CX5-CX14) -> 0 | CY15: =IF(CY2="","",CY5-CY14) -> 0 | CZ15: =IF(CZ2="","",CZ5-CZ14) -> 0 | DA15: =IF(DA2="","",DA5-DA14) -> 0 | ... DE15: =IF(DE2="","",DE5-DE14) -> 0
A16: RECEITA SEM SUCUMBÊNCIAS | Z16: =IF(Z2="","",Z2-Z12) -> 2080493.2 | AA16: =IF(AA2="","",AA2-AA12) -> 1557878.4 | AB16: =IF(AB2="","",AB2-AB12) -> 2467867 | AC16: =IF(AC2="","",AC2-AC12) -> 2077416.3 | AD16: =IF(AD2="","",AD2-AD12) -> 2023994.4 | AE16: =IF(AE2="","",AE2-AE12) -> 1893787.9 | AF16: =IF(AF2="","",AF2-AF12) -> 2432703.7 | AG16: =IF(AG2="","",AG2-AG12) -> 1729132.9 | ... CG16: =IF(CG2="","",CG2-CG12) -> 4422740.2 | CH16: 4035615.7 | CI16: 3696882.3 | CJ16: 3650898.6 | CK16: 3617997.5 | CL16: 3034277.6 | CM16: 4071314.3 | CN16: 4413230.1 | CO16: 4249190.3 | CP16: 4032584.3 | CQ16: 3873651.7 | CR16: 4434287.5 | CS16: 6845733.2 | CT16: =IF(CT2="","",CT2-CT12) -> 3408484.5 | CU16: =IF(CU2="","",CU2-CU12) -> 3212763.3 | CV16: =IF(CV2="","",CV2-CV12) -> 4695972.1 | CW16: =IF(CW2="","",CW2-CW12) -> 0 | CX16: =IF(CX2="","",CX2-CX12) -> 0 | CY16: =IF(CY2="","",CY2-CY12) -> 0 | CZ16: =IF(CZ2="","",CZ2-CZ12) -> 0 | DA16: =IF(DA2="","",DA2-DA12) -> 0 | ... DE16: =IF(DE2="","",DE2-DE12) -> 0
A17: CUSTOS SEM SUCUMBÊNCIAS | Z17: =IF(Z2="","",Z3+Z4+Z15) -> 1758679.3 | AA17: =IF(AA2="","",AA3+AA4+AA15) -> 1616060.5 | AB17: =IF(AB2="","",AB3+AB4+AB15) -> 1486808.5 | AC17: =IF(AC2="","",AC3+AC4+AC15) -> 1427966.4 | AD17: =IF(AD2="","",AD3+AD4+AD15) -> 1325241.1 | AE17: =IF(AE2="","",AE3+AE4+AE15) -> 1266160.4 | AF17: =IF(AF2="","",AF3+AF4+AF15) -> 1533317.3 | AG17: =IF(AG2="","",AG3+AG4+AG15) -> 1517804.3 | ... CG17: =IF(CG2="","",CG3+CG4+CG15) -> 3886001.8 | CH17: 3397254.3 | CI17: 3337042.5 | CJ17: 3410375.7 | CK17: 3389422.2 | CL17: 3388243.6 | CM17: 3639954.4 | CN17: 3684327.1 | CO17: 3521967.5 | CP17: 3970318.1 | CQ17: 3607699.6 | CR17: 4022690.2 | CS17: 4417529.2 | CT17: =IF(CT2="","",CT3+CT4+CT15) -> 3833706.3 | CU17: =IF(CU2="","",CU3+CU4+CU15) -> 3627105.8 | CV17: =IF(CV2="","",CV3+CV4+CV15) -> 3903787.4 | CW17: =IF(CW2="","",CW3+CW4+CW15) -> 0 | CX17: =IF(CX2="","",CX3+CX4+CX15) -> 0 | CY17: =IF(CY2="","",CY3+CY4+CY15) -> 0 | CZ17: =IF(CZ2="","",CZ3+CZ4+CZ15) -> 0 | DA17: =IF(DA2="","",DA3+DA4+DA15) -> 0 | ... DE17: =IF(DE2="","",DE3+DE4+DE15) -> 0
A18: RESULTADO SEM SUCUMBÊNCIAS | Z18: =Z16-Z3-Z4-Z5 -> 316967.94 | AA18: =AA16-AA3-AA4-AA5 -> -59721.478 | AB18: =AB16-AB3-AB4-AB5 -> 980149.12 | AC18: =AC16-AC3-AC4-AC5 -> 648542.94 | AD18: =AD16-AD3-AD4-AD5 -> 697341.82 | AE18: =AE16-AE3-AE4-AE5 -> 620997.47 | AF18: =AF16-AF3-AF4-AF5 -> 897698.99 | AG18: =AG16-AG3-AG4-AG5 -> 209101.34 | ... BU18: =BU16-BU3-BU4-BU5 -> 1235986.7 | BV18: =IF(BV2="","",BV16-BV3-BV4-BV5) -> 302928.52 | BW18: =IF(BW2="","",BW16-BW3-BW4-BW5) -> 348228.9 | BX18: =IF(BX2="","",BX16-BX3-BX4-BX5) -> -214159.64 | BY18: =IF(BY2="","",BY16-BY3-BY4-BY5) -> 463571.29 | BZ18: =IF(BZ2="","",BZ16-BZ3-BZ4-BZ5) -> 694092.16 | CA18: =IF(CA2="","",CA16-CA3-CA4-CA5) -> 961867.52 | CB18: =IF(CB2="","",CB16-CB3-CB4-CB5) -> 1050297.5 | CC18: =IF(CC2="","",CC16-CC3-CC4-CC5) -> 117808.5 | ... CG18: =IF(CG2="","",CG16-CG3-CG4-CG5) -> 447801.84 | CH18: 601657.49 | CI18: 320902.64 | CJ18: 200793.38 | CK18: 196412.26 | CL18: -405359.37 | CM18: 408039.73 | CN18: 717625.07 | CO18: 669281.75 | CP18: 23476.89 | CQ18: 223284.21 | CR18: 386846.38 | CS18: 2378033.9 | CT18: =IF(CT2="","",CT16-CT3-CT4-CT5) -> -468279.07 | CU18: =IF(CU2="","",CU16-CU3-CU4-CU5) -> -455440.52 | CV18: =IF(CV2="","",CV16-CV3-CV4-CV5) -> 792184.77 | CW18: =IF(CW2="","",CW16-CW3-CW4-CW5) -> 0 | CX18: =IF(CX2="","",CX16-CX3-CX4-CX5) -> 0 | CY18: =IF(CY2="","",CY16-CY3-CY4-CY5) -> 0 | CZ18: =IF(CZ2="","",CZ16-CZ3-CZ4-CZ5) -> 0 | DA18: =IF(DA2="","",DA16-DA3-DA4-DA5) -> 0 | ... DE18: =IF(DE2="","",DE16-DE3-DE4-DE5) -> 0
A19: RESULTADO SEM SUCUMBÊNCIAS PAINEL | Z19: =IF(Z2="","",Z16-Z17) -> 321813.9 | AA19: =IF(AA2="","",AA16-AA17) -> -58182.105 | AB19: =IF(AB2="","",AB16-AB17) -> 981058.56 | AC19: =IF(AC2="","",AC16-AC17) -> 649449.9 | AD19: =IF(AD2="","",AD16-AD17) -> 698753.28 | AE19: =IF(AE2="","",AE16-AE17) -> 627627.46 | AF19: =IF(AF2="","",AF16-AF17) -> 899386.45 | AG19: =IF(AG2="","",AG16-AG17) -> 211328.52 | ... CG19: =IF(CG2="","",CG16-CG17) -> 536738.41 | CH19: 638361.32 | CI19: 359839.83 | CJ19: 240522.95 | CK19: 228575.26 | CL19: -353966.04 | CM19: 431359.93 | CN19: 728903 | CO19: 727222.79 | CP19: 62266.126 | CQ19: 265952.08 | CR19: 411597.3 | CS19: 2428203.9 | CT19: =IF(CT2="","",CT16-CT17) -> -425221.73 | CU19: =IF(CU2="","",CU16-CU17) -> -414342.44 | CV19: =IF(CV2="","",CV16-CV17) -> 792184.77 | CW19: =IF(CW2="","",CW16-CW17) -> 0 | CX19: =IF(CX2="","",CX16-CX17) -> 0 | CY19: =IF(CY2="","",CY16-CY17) -> 0 | CZ19: =IF(CZ2="","",CZ16-CZ17) -> 0 | DA19: =IF(DA2="","",DA16-DA17) -> 0 | ... DE19: =IF(DE2="","",DE16-DE17) -> 0
A20: INTERCOMPANY | BJ20: 0 | BK20: 210000 | BL20: 80000 | BM20: 80000 | BN20: 80000 | BO20: 80000 | BP20: 0 | BQ20: 0 | BR20: 110000 | BS20: 170000 | BT20: 0 | BU20: 400000 | BV20: 50000 | BW20: 0 | BX20: 0 | BY20: 0 | BZ20: 0 | CA20: 0 | CB20: 0 | CC20: 0 | CD20: 0 | CE20: 0 | CF20: 400000 | CG20: 500000 | CH20: 0 | CI20: 0 | CJ20: 0 | CK20: 0 | CL20: 0 | CM20: 0 | CN20: 0 | CO20: 0 | CP20: 0 | CQ20: 0 | CR20: 0 | CS20: 0 | CT20: =IF(CT2="","",[2]Receita!B220) -> 0 | CU20: =IF(CU2="","",[2]Receita!C220) -> 0 | CV20: =IF(CV2="","",[2]Receita!D220) -> 0 | CW20: =IF(CW2="","",[2]Receita!E220) -> 0 | CX20: =IF(CX2="","",[2]Receita!F220) -> 0 | CY20: =IF(CY2="","",[2]Receita!G220) -> 0 | CZ20: =IF(CZ2="","",[2]Receita!H220) -> 0 | DA20: =IF(DA2="","",[2]Receita!I220) -> 0 | ... DE20: =IF(DE2="","",[2]Receita!M220) -> 0
A21: VALOR LEGAL | CE21: ='[6]Valor Legal'!$BQ$54+'[6]Valor Legal'!$BQ$61 -> 45894.979 | CF21: ='[6]Valor Legal'!$BX$54+'[6]Valor Legal'!$BX$61 -> 6215.8882 | CG21: ='[6]Valor Legal'!$CE$54+'[6]Valor Legal'!$CE$61 -> 91797.278 | CH21: 22489.233 | CI21: 41333.128 | CJ21: 44330.35 | CK21: 30862.173 | CL21: 68647.997 | CM21: 20028.889 | CN21: 30481.665 | CO21: 50200.221 | CP21: 62569.331 | CQ21: 77234.868 | CR21: 59360.301 | CS21: 59907.791 | CT21: =IF(CT2="","",[2]Recupera!$F$176+[2]Recupera!$F$184) -> 96591.414 | CU21: =IF(CU2="","",[2]Recupera!$M$176+[2]Recupera!$M$184) -> 99851.769 | CV21: =IF(CV2="","",[2]Recupera!$T$176+[2]Recupera!$T$184) -> 158860.76 | CW21: =IF(CW2="","",[2]Recupera!$AA$176+[2]Recupera!$AA$184) -> 0 | CX21: =IF(CX2="","",[2]Recupera!$AH$176+[2]Recupera!$AH$184) -> 0 | CY21: =IF(CY2="","",[2]Recupera!$AO$176+[2]Recupera!$AO$184) -> 0 | CZ21: =IF(CZ2="","",[2]Recupera!$AV$176+[2]Recupera!$AV$184) -> 0 | DA21: =IF(DA2="","",[2]Recupera!$BC$176+[2]Recupera!$BC$184) -> 0 | DB21: =IF(DB2="","",[2]Recupera!$BJ$176+[2]Recupera!$BJ$184) -> 0 | DC21: =IF(DC2="","",[2]Recupera!$BQ$176+[2]Recupera!$BQ$184) -> 0 | DD21: =IF(DD2="","",[2]Recupera!$BX$176+[2]Recupera!$BX$184) -> 0 | DE21: =IF(DE2="","",[2]Recupera!$CE$176+[2]Recupera!$CE$184) -> 0
A22: SUCUMB LÍQUIDA | BV22: =IFERROR(BV12-BV13-BV23-BV12*0.1,"") -> 18583.375 | BW22: =IFERROR(BW12-BW13-BW23-BW12*0.1,"") -> 194132.92 | BX22: =IFERROR(BX12-BX13-BX23-BX12*0.1,"") -> 106430.63 | BY22: =IFERROR(BY12-BY13-BY23-BY12*0.1,"") -> -776.622 | BZ22: =IFERROR(BZ12-BZ13-BZ23-BZ12*0.1,"") -> 31914.882 | CA22: =IFERROR(CA12-CA13-CA23-CA12*0.1,"") -> 124939.11 | CB22: =IFERROR(CB12-CB13-CB23-CB12*0.1,"") -> 218859.36 | CC22: =IFERROR(CC12-CC13-CC23-CC12*0.1,"") -> 195272.29 | ... CG22: =IFERROR(CG12-CG13-CG23-CG12*0.1,"") -> 746460.23 | CH22: 296944.1 | CI22: 296431.26 | CJ22: 313439.61 | CK22: 228184.1 | CL22: 474354.26 | CM22: 55607.742 | CN22: 35551.042 | CO22: 477323.64 | CP22: 62001.919 | CQ22: 321352.21 | CR22: 134963.69 | CS22: 407018.19 | CT22: =IFERROR(CT12-CT13-CT23-CT12*0.1,"") -> 353651.41 | CU22: =IFERROR(CU12-CU13-CU23-CU12*0.1,"") -> 324456.72 | CV22: =IFERROR(CV12-CV13-CV23-CV12*0.1,"") -> -74268.38 | CW22: =IFERROR(CW12-CW13-CW23-CW12*0.1,"") -> 0 | CX22: =IFERROR(CX12-CX13-CX23-CX12*0.1,"") -> 0 | CY22: =IFERROR(CY12-CY13-CY23-CY12*0.1,"") -> 0 | CZ22: =IFERROR(CZ12-CZ13-CZ23-CZ12*0.1,"") -> 0 | DA22: =IFERROR(DA12-DA13-DA23-DA12*0.1,"") -> 0 | ... DE22: =IFERROR(DE12-DE13-DE23-DE12*0.1,"") -> 0
A23: VL DD | CE23: 45894.979 | CF23: 6215.8882 | CG23: 5292.2577 | CH23: 5010.1128 | CI23: 7679.8074 | CJ23: 13659.403 | CK23: 13024.136 | CL23: 13363.604 | CM23: 12984.261 | CN23: 29778.562 | CO23: 22424.199 | CP23: 34808.085 | CQ23: 31048.795 | CR23: 24300.526 | CS23: 22950.773 | CT23: =IF(CT2="","",[2]Recupera!$F$176) -> 24750.633 | CU23: =IF(CU2="","",[2]Recupera!$M$176) -> 21875.415 | CV23: =IF(CV2="","",[2]Recupera!$T$176) -> 42960.22 | CW23: =IF(CW2="","",[2]Recupera!$AA$176) -> 0 | CX23: =IF(CX2="","",[2]Recupera!$AH$176) -> 0 | CY23: =IF(CY2="","",[2]Recupera!$AO$176) -> 0 | CZ23: =IF(CZ2="","",[2]Recupera!$AV$176) -> 0 | DA23: =IF(DA2="","",[2]Recupera!$BC$176) -> 0 | DB23: =IF(DB2="","",[2]Recupera!$BJ$176) -> 0 | DC23: =IF(DC2="","",[2]Recupera!$BQ$176) -> 0 | DD23: =IF(DD2="","",[2]Recupera!$BX$176) -> 0 | DE23: =IF(DE2="","",[2]Recupera!$CE$176) -> 0
A24: SUCUMB ORÇADA | CH24: 141666.67 | CI24: 141666.67 | CJ24: 141666.67 | CK24: 141666.67 | CL24: 141666.67 | CM24: 141666.67 | CN24: 141666.67 | CO24: 141666.67 | CP24: 141666.67 | CQ24: 141666.67 | CR24: 141666.67 | CS24: 141666.67 | CT24: =[2]Recupera!$D$8 -> 150000 | CU24: =[2]Recupera!$K$8 -> 150000 | CV24: =[2]Recupera!$R$8 -> 150000 | CW24: =[2]Recupera!$Y$8 -> 150000 | CX24: =[2]Recupera!$AF$8 -> 150000 | CY24: =[2]Recupera!$AM$8 -> 150000 | CZ24: =[2]Recupera!$AT$8 -> 150000 | DA24: =[2]Recupera!$BA$8 -> 150000 | DB24: =[2]Recupera!$BH$8 -> 150000 | DC24: =[2]Recupera!$BO$8 -> 150000 | DD24: =[2]Recupera!$BV$8 -> 150000 | DE24: =[2]Recupera!$CC$8 -> 150000
A25: TOTAL ORÇADO | CH25: 4231546.7 | CI25: 4391466.7 | CJ25: 3930886.7 | CK25: 4214399.7 | CL25: 4491699.7 | CM25: 4496699.7 | CN25: 4546699.7 | CO25: 4582399.7 | CP25: 4492399.7 | CQ25: 4516599.7 | CR25: 4536599.7 | CS25: 4526599.7 | CT25: =[2]Total!$B$35 -> 3495609.3 | CU25: =[2]Total!$P$35 -> 3650042.4 | CV25: =[2]Total!$AD$35 -> 4860256.6 | CW25: =[2]Total!$AR$35 -> 4674335.2 | CX25: =[2]Total!$BF$35 -> 4763068.3 | CY25: =[2]Total!$BT$35 -> 4772526.3 | CZ25: =[2]Total!$CH$35 -> 4948793.2 | DA25: =[2]Total!$CV$35 -> 4948793.2 | DB25: =[2]Total!$DJ$35 -> 4948793.2 | DC25: =[2]Total!$DX$35 -> 4995060.2 | DD25: =[2]Total!$EL$35 -> 4948793.2 | DE25: =[2]Total!$EZ$35 -> 4948793.2
A26: CONTRATUAIS ORÇADO | CH26: 4089880 | CI26: 4249800 | CJ26: 3789220 | CK26: 4072733 | CL26: 4350033 | CM26: 4355033 | CN26: 4405033 | CO26: 4440733 | CP26: 4350733 | CQ26: 4374933 | CR26: 4394933 | CS26: 4384933 | CT26: =IF(CT2="","",CT25-CT24) -> 3345609.3 | CU26: =IF(CU2="","",CU25-CU24) -> 3500042.4 | CV26: =IF(CV2="","",CV25-CV24) -> 4710256.6 | CW26: =IF(CW2="","",CW25-CW24) -> 4524335.2 | CX26: =IF(CX2="","",CX25-CX24) -> 4613068.3 | CY26: =IF(CY2="","",CY25-CY24) -> 4622526.3 | CZ26: =IF(CZ2="","",CZ25-CZ24) -> 4798793.2 | DA26: =IF(DA2="","",DA25-DA24) -> 4798793.2 | ... DE26: =IF(DE2="","",DE25-DE24) -> 4798793.2
A27: RESULTADO SEM SUCUMBÊNCIAS LÍQUIDA | BV27: =BV9-BV22 -> 329923.1 | BW27: =BW9-BW22 -> 411830.02 | BX27: =BX9-BX22 -> -187042.34 | BY27: =BY9-BY22 -> 503539.33 | BZ27: =BZ9-BZ22 -> 774305.36 | CA27: =CA9-CA22 -> 1024319.9 | CB27: =CB9-CB22 -> 1242056.1 | CC27: =CC9-CC22 -> 226346.58 | ... CG27: =CG9-CG22 -> 590707.28 | CH27: 671751.68 | CI27: 413843.31 | CJ27: 284649.47 | CK27: 289858.21 | CL27: -365780.32 | CM27: 585633.96 | CN27: 794853.29 | CO27: 771368.52 | CP27: 349367.33 | CQ27: 328610.63 | CR27: 499391.88 | CS27: 2472715.6 | CT27: =IF(CT2="","",CT9-CT22) -> -391357.06 | CU27: =IF(CU2="","",CU9-CU22) -> -368916.46 | CV27: =IF(CV2="","",CV9-CV22) -> 866453.16 | CW27: =IF(CW2="","",CW9-CW22) -> 0 | CX27: =IF(CX2="","",CX9-CX22) -> 0 | CY27: =IF(CY2="","",CY9-CY22) -> 0 | CZ27: =IF(CZ2="","",CZ9-CZ22) -> 0 | DA27: =IF(DA2="","",DA9-DA22) -> 0 | ... DE27: =IF(DE2="","",DE9-DE22) -> 0
A28: RECEITA SEM INTERCOMPANY | B28: =B2-B20 -> 1307223.8 | C28: =C2-C20 -> 1533151.6 | D28: =D2-D20 -> 990409.83 | E28: =E2-E20 -> 1675538.8 | F28: =F2-F20 -> 1390304.1 | G28: =G2-G20 -> 1429726.9 | H28: =H2-H20 -> 1617844.9 | I28: =I2-I20 -> 1754379.8 | ... CG28: =CG2-CG20 -> 4812105.9 | CH28: 4402653.9 | CI28: 4086254.3 | CJ28: 4048194.3 | CK28: 3939627.5 | CL28: 3548210.9 | CM28: 4304516.3 | CN28: 4526009.4 | CO28: 4828600.7 | CP28: 4420476.6 | CQ28: 4300330.3 | CR28: 4681796.7 | CS28: 7347433 | CT28: =IF(CT2="","",CT2-CT20) -> 3839058 | CU28: =IF(CU2="","",CU2-CU20) -> 3623744.1 | CV28: =IF(CV2="","",CV2-CV20) -> 4695972.1 | CW28: =IF(CW2="","",CW2-CW20) -> 0 | CX28: =IF(CX2="","",CX2-CX20) -> 0 | CY28: =IF(CY2="","",CY2-CY20) -> 0 | CZ28: =IF(CZ2="","",CZ2-CZ20) -> 0 | DA28: =IF(DA2="","",DA2-DA20) -> 0 | ... DE28: =IF(DE2="","",DE2-DE20) -> 0
A29: CUSTOS E DESPESAS SEM INTERCOMPANY | B29: =B8-B20 -> 1251905.1 | C29: =C8-C20 -> 1154457.8 | D29: =D8-D20 -> 1183242.9 | E29: =E8-E20 -> 1291915.3 | F29: =F8-F20 -> 1293411 | G29: =G8-G20 -> 1306797 | H29: =H8-H20 -> 1485977.8 | I29: =I8-I20 -> 1509039.3 | ... CG29: =CG8-CG20 -> 3474938.4 | CH29: 3433958.2 | CI29: 3375979.7 | CJ29: 3450105.3 | CK29: 3421585.2 | CL29: 3439636.9 | CM29: 3663274.6 | CN29: 3695605.1 | CO29: 3579908.6 | CP29: 4009107.4 | CQ29: 3650367.4 | CR29: 4047441.1 | CS29: 4467699.2 | CT29: =IF(CT2="","",CT8-CT20) -> 3876763.6 | CU29: =IF(CU2="","",CU8-CU20) -> 3668203.8 | CV29: =IF(CV2="","",CV8-CV20) -> 3903787.4 | CW29: =IF(CW2="","",CW8-CW20) -> 0 | CX29: =IF(CX2="","",CX8-CX20) -> 0 | CY29: =IF(CY2="","",CY8-CY20) -> 0 | CZ29: =IF(CZ2="","",CZ8-CZ20) -> 0 | DA29: =IF(DA2="","",DA8-DA20) -> 0 | ... DE29: =IF(DE2="","",DE8-DE20) -> 0
A30: RESULTADO SEM INTERCOMPANY | B30: =B28-B29 -> 55318.732 | C30: =C28-C29 -> 378693.83 | D30: =D28-D29 -> -192833.08 | E30: =E28-E29 -> 383623.47 | F30: =F28-F29 -> 96893.083 | G30: =G28-G29 -> 122929.91 | H30: =H28-H29 -> 131867.03 | I30: =I28-I29 -> 245340.54 | ... CG30: =CG28-CG29 -> 1337167.5 | CH30: 968695.78 | CI30: 710274.57 | CJ30: 598089.08 | CK30: 518042.31 | CL30: 108573.95 | CM30: 641241.7 | CN30: 830404.33 | CO30: 1248692.2 | CP30: 411369.25 | CQ30: 649962.84 | CR30: 634355.57 | CS30: 2879733.8 | CT30: =IF(CT2="","",CT28-CT29) -> -37705.652 | CU30: =IF(CU2="","",CU28-CU29) -> -44459.741 | CV30: =IF(CV2="","",CV28-CV29) -> 792184.77 | CW30: =IF(CW2="","",CW28-CW29) -> 0 | CX30: =IF(CX2="","",CX28-CX29) -> 0 | CY30: =IF(CY2="","",CY28-CY29) -> 0 | CZ30: =IF(CZ2="","",CZ28-CZ29) -> 0 | DA30: =IF(DA2="","",DA28-DA29) -> 0 | ... DE30: =IF(DE2="","",DE28-DE29) -> 0

Sheet Honorários
A1: DATA | B1: TOTAL FLUXO | C1: ATOS/PREPOSTOS | D1: SUCUMBÊNCIAS | E1: GLOSAS | F1: VALORES RETROATIVOS | G1: TOTAL | H1: Hora
A2: 43466 | B2: 1467400.1 | G2: =B2+C2+D2+E2 -> 1467400.1 | H2: =NOW() -> 46134.669
A3: 43497 | B3: 1032717.8 | G3: =B3+C3+D3+E3 -> 1032717.8
A4: 43525 | B4: 1313738 | G4: =B4+C4+D4+E4 -> 1313738
A5: 43556 | B5: 1330213.9 | G5: =B5+C5+D5+E5 -> 1330213.9
A6: 43586 | B6: 1973924 | G6: =B6+C6+D6+E6 -> 1973924
A7: 43617 | B7: 2136174.2 | G7: =B7+C7+D7+E7 -> 2136174.2
A8: 43647 | B8: 1983098.6 | G8: =B8+C8+D8+E8 -> 1983098.6
A9: 43678 | B9: 2276787.9 | G9: =B9+C9+D9+E9 -> 2276787.9
A10: 43709 | B10: 1849436 | G10: =B10+C10+D10+E10 -> 1849436
A11: 43739 | B11: 1853373.7 | G11: =B11+C11+D11+E11 -> 1853373.7
A12: 43770 | B12: 2489722.6 | G12: =B12+C12+D12+E12 -> 2489722.6
A13: 43800 | B13: 1833456.7 | G13: =B13+C13+D13+E13 -> 1833456.7
A14: 43831 | B14: 2079332.4 | C14: 0 | D14: 48459.63 | E14: 1160.72 | F14: 0 | G14: =B14+C14+D14+E14 -> 2128952.8
A15: 43862 | B15: 1557158.3 | C15: 0 | D15: 15393.73 | E15: 720.08 | F15: 0 | G15: =B15+C15+D15+E15 -> 1573272.1
A16: 43891 | B16: 2446334.3 | C16: 2080.1 | D16: 9094.42 | E16: 19452.58 | F16: 0 | G16: =B16+C16+D16+E16 -> 2476961.4
A17: 43922 | B17: 2077416.3 | C17: 0 | D17: 9069.62 | E17: 0 | F17: 0 | G17: =B17+C17+D17+E17 -> 2086485.9
A18: 43952 | B18: 2012991.2 | C18: 10395 | D18: 14114.65 | E18: 608.23 | F18: 0 | G18: =B18+C18+D18+E18 -> 2038109.1
A19: 43983 | B19: 1893356 | C19: 0 | D19: 66299.88 | E19: 431.84 | F19: 0 | G19: =B19+C19+D19+E19 -> 1960087.8
A20: 44013 | B20: 2424434.8 | C20: 60 | D20: 16874.65 | E20: 8208.94 | F20: 0 | G20: =B20+C20+D20+E20 -> 2449578.4
A21: 44044 | B21: 1728524.6 | C21: 0 | D21: 22271.86 | E21: 608.23 | F21: 0 | G21: =B21+C21+D21+E21 -> 1751404.7
A22: 44075 | B22: 2622040.1 | C22: 290 | D22: 9498.26 | E22: 4276.55 | F22: 0 | G22: =B22+C22+D22+E22 -> 2636104.9
A23: 44105 | B23: 1936416.9 | C23: 580 | D23: 46340.98 | E23: 7719.49 | F23: 0 | G23: =B23+C23+D23+E23 -> 1991057.4
A24: 44136 | B24: 2820577.8 | C24: 700 | D24: 11279 | E24: 57920.46 | F24: 0 | G24: =B24+C24+D24+E24 -> 2890477.2
A25: 44166 | B25: 2630555 | C25: 1015 | D25: 35578.24 | E25: 5394.13 | F25: 0 | G25: =B25+C25+D25+E25 -> 2672542.4
... A33: 44409 | B33: 2099963.6 | C33: 0 | D33: 45636.69 | E33: 35269.8 | F33: 0 | G33: =B33+C33+D33+E33 -> 2180870.1
A34: 44440 | B34: 2200749.7 | C34: 2448.1 | D34: =[7]Receita!$J$315+[7]Receita!$J$318 -> 45175.41 | E34: 25874.19 | F34: 0 | G34: =B34+C34+D34+E34 -> 2274247.4
A35: 44470 | B35: 2525135.5 | C35: 1885 | D35: =[7]Receita!$K$315+[7]Receita!$K$318 -> 39850.58 | E35: 21889.69 | F35: 0 | G35: =B35+C35+D35+E35 -> 2588760.7
A36: 44501 | B36: 2472022.3 | C36: 0 | D36: 83465.23 | E36: 25793.59 | F36: 0 | G36: =B36+C36+D36+E36 -> 2581281.1
A37: 44531 | B37: 2899936.4 | C37: 2150 | D37: 86874.45 | E37: 13816.28 | F37: 0 | G37: =B37+C37+D37+E37 -> 3002777.1
A38: 44562 | B38: 2194991.6 | C38: 290 | D38: 29746.63 | E38: =10077.12+1670 -> 11747.12 | F38: 0 | G38: =B38+C38+D38+E38 -> 2236775.4
A39: 44593 | B39: 1407956.7 | C39: 60 | D39: 18941.76 | E39: 5696.73 | F39: 0 | G39: =B39+C39+D39+E39 -> 1432655.2
A40: 44621 | B40: 1972315.4 | C40: 435 | D40: 32915.16 | E40: 5693.35 | F40: 0 | G40: =B40+C40+D40+E40 -> 2011358.9
A41: 44652 | B41: 2545081.6 | C41: 435 | D41: 106067.72 | E41: 7446.7 | F41: 0 | G41: =B41+C41+D41+E41 -> 2659031
A42: 44682 | B42: 2927889.2 | C42: 180 | D42: 64119.41 | E42: 14391.15 | F42: 0 | G42: =B42+C42+D42+E42 -> 3006579.8
A43: 44713 | B43: 2337673.7 | C43: 1885 | D43: =[4]Receita!$G$315+[4]Receita!$G$318 -> 111006.47 | E43: 14336.19 | F43: 0 | G43: =B43+C43+D43+E43 -> 2464901.4
A44: 44743 | B44: 2487139.5 | C44: 650 | D44: 11551.85 | E44: 2040.76 | F44: 0 | G44: =B44+C44+D44+E44 -> 2501382.1
A45: 44774 | B45: 2068851.1 | C45: 530 | D45: 130378.64 | E45: 5100.35 | F45: 0 | G45: =B45+C45+D45+E45 -> 2204860.1
A46: 44805 | B46: 2481115.3 | C46: 2650 | D46: 66227.94 | E46: 6902.78 | F46: 0 | G46: =B46+C46+D46+E46 -> 2556896
A47: 44835 | B47: 2619228.2 | C47: 0 | D47: 80018.85 | E47: 8450.42 | F47: 0 | G47: =B47+C47+D47+E47 -> 2707697.4
...

Sheet GLOSAS
A1: Grupo | B1: Data | C1: 2019 | D1: 43831 | E1: 43862 | F1: 43891 | G1: 43922 | H1: 43952 | I1: 43983 | J1: 44013 | K1: 44044 | L1: 44075 | M1: 44105 | N1: 44136 | O1: 44166 | P1: 2020 | Q1: 44197 | R1: 44228 | S1: 44256 | T1: 44287 | U1: 44317 | V1: 44348 | W1: 44378 | X1: 44409 | Y1: 44440 | Z1: 44470 | AA1: 44501 | AB1: 44531 | AC1: 2021 | AD1: 44562 | AE1: 44593 | AF1: 44621 | AG1: 44652 | AH1: 44682 | AI1: 44713 | AJ1: 44743 | AK1: 44774 | AL1: 44805 | AM1: 44835 | AN1: 44866 | AO1: 44896 | AP1: 2022 | AQ1: 44927 | AR1: 44958 | AS1: 44986 | AT1: 45017 | AU1: 45047 | AV1: 45078 | AW1: 45108 | AX1: 45139 | AY1: 45170 | AZ1: 45200 | BA1: 45231 | BB1: 45261 | BC1: 2023 | BD1: 45292 | BE1: 45323 | BF1: 45352 | BG1: 45383 | BH1: 45413 | BI1: 45444 | BJ1: 45474 | BK1: 45505 | BL1: 45536 | BM1: 45566 | BN1: 45597 | BO1: 45627 | BP1: 2024 | BQ1: 45658 | BR1: 45689 | BS1: 45717 | BT1: 45748 | BU1: 45778 | BV1: 45809 | BW1: 45839 | BX1: 45870 | BY1: 45901 | BZ1: 45931 | CA1: 45962 | CB1: 45992 | CC1: 2025 | CD1: 46023 | CE1: 46054 | CF1: 46082 | CG1: 46113 | CH1: 46143 | CI1: 46174 | CJ1: 46204 | CK1: 46235 | CL1: 46266 | CM1: 46296 | CN1: 46327 | CO1: 46357 | CP1: 2026
A2: SANEAMENTO | B2: SANEAMENTO | C2: 0 | D2: 0 | E2: 0 | F2: 0 | G2: 0 | H2: 0 | I2: 0 | J2: 0 | K2: 0 | L2: 0 | M2: 0 | N2: 0 | O2: 0 | P2: =SUM(D2:O2) -> 0 | Q2: 0 | R2: 0 | S2: 0 | T2: 0 | U2: 0 | V2: 0 | W2: 0 | X2: 0 | Y2: 578.97 | Z2: 0 | AA2: 0 | AB2: 0 | AC2: =SUM(Q2:AB2) -> 578.97 | AD2: 0 | AE2: 0 | AF2: 0 | AG2: 0 | AH2: 0 | AI2: 0 | AJ2: 0 | AK2: 0 | AL2: 700 | AM2: 2042 | AN2: 900.46 | AO2: 0 | AP2: =SUM(AD2:AO2) -> 3642.46 | AQ2: 0 | AR2: 0 | AS2: 1219.97 | AT2: 0 | AU2: 2304.14 | AV2: 0 | AW2: 1877.3 | AX2: 0 | AY2: 0 | AZ2: 0 | BA2: 0 | BB2: 0 | BC2: =SUM(AQ2:BB2) -> 5401.41 | BD2: 0 | BE2: 6279.55 | BF2: 0 | BG2: 10864.74 | BH2: 0 | BI2: 0 | BJ2: 3000 | BK2: 0 | BL2: 8000 | BM2: 2430.74 | BN2: 0 | BO2: 0 | BP2: =SUM(BD2:BO2) -> 30575.03 | BQ2: 0 | BR2: 0 | BS2: 0 | BT2: 0 | BU2: 0 | BV2: 0 | BW2: 0 | BX2: 0 | BY2: 0 | BZ2: 0 | CA2: 0 | CB2: 0 | CC2: =SUM(BQ2:CB2) -> 0 | CD2: 0 | CE2: 0 | CF2: 0 | CG2: 0 | CH2: 0 | CI2: 0 | CJ2: 0 | CK2: 0 | CL2: 0 | CM2: 0 | CN2: 0 | CO2: 0 | CP2: =SUM(CD2:CO2) -> 0
A3: SANEAMENTO | B3: SANEAMENTO - BRK | C3: 0 | D3: 0 | E3: 0 | F3: 0 | G3: 0 | H3: 0 | I3: 0 | J3: 0 | K3: 0 | L3: 0 | M3: 0 | N3: 0 | O3: 0 | P3: =SUM(D3:O3) -> 0 | Q3: 0 | R3: 0 | S3: 0 | T3: 0 | U3: 0 | V3: 0 | W3: 0 | X3: 0 | Y3: 0 | Z3: 0 | AA3: 0 | AB3: 0 | AC3: =SUM(Q3:AB3) -> 0 | AD3: 0 | AE3: 0 | AF3: 0 | AG3: 0 | AH3: 0 | AI3: 0 | AJ3: 0 | AK3: 0 | AL3: 0 | AM3: 0 | AN3: 0 | AO3: 0 | AP3: =SUM(AD3:AO3) -> 0 | AQ3: 0 | AR3: 0 | AS3: 0 | AT3: 0 | AU3: 0 | AV3: 0 | AW3: 0 | AX3: 0 | AY3: 0 | AZ3: 0 | BA3: 0 | BB3: 0 | BC3: =SUM(AQ3:BB3) -> 0 | BD3: 0 | BE3: 0 | BF3: 0 | BG3: 0 | BH3: 0 | BI3: 0 | BJ3: 0 | BK3: 0 | BL3: 0 | BM3: 0 | BN3: 0 | BO3: 0 | BP3: =SUM(BD3:BO3) -> 0 | BQ3: 0 | BR3: 6255.98 | BS3: 1172.33 | BT3: 0 | BU3: 254.94 | BV3: 77515.48 | BW3: 12847.05 | BX3: 4500 | BY3: 4385.96 | BZ3: 8501.55 | CA3: 8500 | CB3: 0 | CC3: =SUM(BQ3:CB3) -> 123933.29 | CD3: =VLOOKUP("Condenação",[2]Saneamento!$A67:$CH109,CD46,0)+VLOOKUP("Penalidades/Irregularidades",[2]Saneamento!$A67:$CH109,CD46,0) -> 0 | CE3: =VLOOKUP("Condenação",[2]Saneamento!$A67:$CH109,CE46,0)+VLOOKUP("Penalidades/Irregularidades",[2]Saneamento!$A67:$CH109,CE46,0) -> 0 | CF3: =VLOOKUP("Condenação",[2]Saneamento!$A67:$CH109,CF46,0)+VLOOKUP("Penalidades/Irregularidades",[2]Saneamento!$A67:$CH109,CF46,0) -> 0 | CG3: =VLOOKUP("Condenação",[2]Saneamento!$A67:$CH109,CG46,0)+VLOOKUP("Penalidades/Irregularidades",[2]Saneamento!$A67:$CH109,CG46,0) -> 0 | CH3: =VLOOKUP("Condenação",[2]Saneamento!$A67:$CH109,CH46,0)+VLOOKUP("Penalidades/Irregularidades",[2]Saneamento!$A67:$CH109,CH46,0) -> 0 | CI3: =VLOOKUP("Condenação",[2]Saneamento!$A67:$CH109,CI46,0)+VLOOKUP("Penalidades/Irregularidades",[2]Saneamento!$A67:$CH109,CI46,0) -> 0 | CJ3: =VLOOKUP("Condenação",[2]Saneamento!$A67:$CH109,CJ46,0)+VLOOKUP("Penalidades/Irregularidades",[2]Saneamento!$A67:$CH109,CJ46,0) -> 0 | CK3: =VLOOKUP("Condenação",[2]Saneamento!$A67:$CH109,CK46,0)+VLOOKUP("Penalidades/Irregularidades",[2]Saneamento!$A67:$CH109,CK46,0) -> 0 | ... CO3: =VLOOKUP("Condenação",[2]Saneamento!$A67:$CH109,CO46,0)+VLOOKUP("Penalidades/Irregularidades",[2]Saneamento!$A67:$CH109,CO46,0) -> 0 | CP3: =SUM(CD3:CO3) -> 0
A4: SANEAMENTO | B4: SANEAMENTO - ÁGUAS DO RIO 1 | C4: 0 | D4: 0 | E4: 0 | F4: 0 | G4: 0 | H4: 0 | I4: 0 | J4: 0 | K4: 0 | L4: 0 | M4: 0 | N4: 0 | O4: 0 | P4: =SUM(D4:O4) -> 0 | Q4: 0 | R4: 0 | S4: 0 | T4: 0 | U4: 0 | V4: 0 | W4: 0 | X4: 0 | Y4: 0 | Z4: 0 | AA4: 0 | AB4: 0 | AC4: =SUM(Q4:AB4) -> 0 | AD4: 0 | AE4: 0 | AF4: 0 | AG4: 0 | AH4: 0 | AI4: 0 | AJ4: 0 | AK4: 0 | AL4: 0 | AM4: 0 | AN4: 0 | AO4: 0 | AP4: =SUM(AD4:AO4) -> 0 | AQ4: 0 | AR4: 0 | AS4: 0 | AT4: 0 | AU4: 0 | AV4: 0 | AW4: 0 | AX4: 0 | AY4: 0 | AZ4: 0 | BA4: 0 | BB4: 0 | BC4: =SUM(AQ4:BB4) -> 0 | BD4: 0 | BE4: 0 | BF4: 0 | BG4: 0 | BH4: 0 | BI4: 0 | BJ4: 0 | BK4: 0 | BL4: 0 | BM4: 0 | BN4: 0 | BO4: 0 | BP4: =SUM(BD4:BO4) -> 0 | BQ4: 0 | BR4: 0 | BS4: 0 | BT4: 0 | BU4: 0 | BV4: 0 | BW4: 0 | BX4: 0 | BY4: 0 | BZ4: 0 | CA4: 0 | CB4: 0 | CC4: =SUM(BQ4:CB4) -> 0 | CD4: =VLOOKUP("Condenação",[2]Saneamento!$A501:$CH543,CD46,0)+VLOOKUP("Penalidades/Irregularidades",[2]Saneamento!$A501:$CH543,CD46,0) -> 0 | CE4: =VLOOKUP("Condenação",[2]Saneamento!$A501:$CH543,CE46,0)+VLOOKUP("Penalidades/Irregularidades",[2]Saneamento!$A501:$CH543,CE46,0) -> 0 | CF4: =VLOOKUP("Condenação",[2]Saneamento!$A501:$CH543,CF46,0)+VLOOKUP("Penalidades/Irregularidades",[2]Saneamento!$A501:$CH543,CF46,0) -> 0 | CG4: =VLOOKUP("Condenação",[2]Saneamento!$A501:$CH543,CG46,0)+VLOOKUP("Penalidades/Irregularidades",[2]Saneamento!$A501:$CH543,CG46,0) -> 0 | CH4: =VLOOKUP("Condenação",[2]Saneamento!$A501:$CH543,CH46,0)+VLOOKUP("Penalidades/Irregularidades",[2]Saneamento!$A501:$CH543,CH46,0) -> 0 | CI4: =VLOOKUP("Condenação",[2]Saneamento!$A501:$CH543,CI46,0)+VLOOKUP("Penalidades/Irregularidades",[2]Saneamento!$A501:$CH543,CI46,0) -> 0 | CJ4: =VLOOKUP("Condenação",[2]Saneamento!$A501:$CH543,CJ46,0)+VLOOKUP("Penalidades/Irregularidades",[2]Saneamento!$A501:$CH543,CJ46,0) -> 0 | CK4: =VLOOKUP("Condenação",[2]Saneamento!$A501:$CH543,CK46,0)+VLOOKUP("Penalidades/Irregularidades",[2]Saneamento!$A501:$CH543,CK46,0) -> 0 | ... CO4: =VLOOKUP("Condenação",[2]Saneamento!$A501:$CH543,CO46,0)+VLOOKUP("Penalidades/Irregularidades",[2]Saneamento!$A501:$CH543,CO46,0) -> 0 | CP4: =SUM(CD4:CO4) -> 0
A5: SANEAMENTO | B5: SANEAMENTO - ÁGUAS DO RIO 4 | C5: 0 | D5: 0 | E5: 0 | F5: 0 | G5: 0 | H5: 0 | I5: 0 | J5: 0 | K5: 0 | L5: 0 | M5: 0 | N5: 0 | O5: 0 | P5: =SUM(D5:O5) -> 0 | Q5: 0 | R5: 0 | S5: 0 | T5: 0 | U5: 0 | V5: 0 | W5: 0 | X5: 0 | Y5: 0 | Z5: 0 | AA5: 0 | AB5: 0 | AC5: =SUM(Q5:AB5) -> 0 | AD5: 0 | AE5: 0 | AF5: 0 | AG5: 0 | AH5: 0 | AI5: 0 | AJ5: 0 | AK5: 0 | AL5: 0 | AM5: 0 | AN5: 0 | AO5: 0 | AP5: =SUM(AD5:AO5) -> 0 | AQ5: 0 | AR5: 0 | AS5: 0 | AT5: 0 | AU5: 0 | AV5: 0 | AW5: 0 | AX5: 0 | AY5: 0 | AZ5: 0 | BA5: 0 | BB5: 0 | BC5: =SUM(AQ5:BB5) -> 0 | BD5: 0 | BE5: 0 | BF5: 0 | BG5: 0 | BH5: 0 | BI5: 0 | BJ5: 0 | BK5: 0 | BL5: 0 | BM5: 0 | BN5: 0 | BO5: 0 | BP5: =SUM(BD5:BO5) -> 0 | BQ5: 0 | BR5: 0 | BS5: 0 | BT5: 0 | BU5: 0 | BV5: 0 | BW5: 0 | BX5: 0 | BY5: 0 | BZ5: 0 | CA5: 0 | CB5: 0 | CC5: =SUM(BQ5:CB5) -> 0 | CD5: =VLOOKUP("Condenação",[2]Saneamento!$A439:$CH481,CD46,0)+VLOOKUP("Penalidades/Irregularidades",[2]Saneamento!$A439:$CH481,CD46,0) -> 0 | CE5: =VLOOKUP("Condenação",[2]Saneamento!$A439:$CH481,CE46,0)+VLOOKUP("Penalidades/Irregularidades",[2]Saneamento!$A439:$CH481,CE46,0) -> 0 | CF5: =VLOOKUP("Condenação",[2]Saneamento!$A439:$CH481,CF46,0)+VLOOKUP("Penalidades/Irregularidades",[2]Saneamento!$A439:$CH481,CF46,0) -> 0 | CG5: =VLOOKUP("Condenação",[2]Saneamento!$A439:$CH481,CG46,0)+VLOOKUP("Penalidades/Irregularidades",[2]Saneamento!$A439:$CH481,CG46,0) -> 0 | CH5: =VLOOKUP("Condenação",[2]Saneamento!$A439:$CH481,CH46,0)+VLOOKUP("Penalidades/Irregularidades",[2]Saneamento!$A439:$CH481,CH46,0) -> 0 | CI5: =VLOOKUP("Condenação",[2]Saneamento!$A439:$CH481,CI46,0)+VLOOKUP("Penalidades/Irregularidades",[2]Saneamento!$A439:$CH481,CI46,0) -> 0 | CJ5: =VLOOKUP("Condenação",[2]Saneamento!$A439:$CH481,CJ46,0)+VLOOKUP("Penalidades/Irregularidades",[2]Saneamento!$A439:$CH481,CJ46,0) -> 0 | CK5: =VLOOKUP("Condenação",[2]Saneamento!$A439:$CH481,CK46,0)+VLOOKUP("Penalidades/Irregularidades",[2]Saneamento!$A439:$CH481,CK46,0) -> 0 | ... CO5: =VLOOKUP("Condenação",[2]Saneamento!$A439:$CH481,CO46,0)+VLOOKUP("Penalidades/Irregularidades",[2]Saneamento!$A439:$CH481,CO46,0) -> 0 | CP5: =SUM(CD5:CO5) -> 0
A6: SANEAMENTO | B6: SANEAMENTO - ÁGUAS DO SERTÃO | C6: 0 | D6: 0 | E6: 0 | F6: 0 | G6: 0 | H6: 0 | I6: 0 | J6: 0 | K6: 0 | L6: 0 | M6: 0 | N6: 0 | O6: 0 | P6: =SUM(D6:O6) -> 0 | Q6: 0 | R6: 0 | S6: 0 | T6: 0 | U6: 0 | V6: 0 | W6: 0 | X6: 0 | Y6: 0 | Z6: 0 | AA6: 0 | AB6: 0 | AC6: =SUM(Q6:AB6) -> 0 | AD6: 0 | AE6: 0 | AF6: 0 | AG6: 0 | AH6: 0 | AI6: 0 | AJ6: 0 | AK6: 0 | AL6: 0 | AM6: 0 | AN6: 0 | AO6: 0 | AP6: =SUM(AD6:AO6) -> 0 | AQ6: 0 | AR6: 0 | AS6: 0 | AT6: 0 | AU6: 0 | AV6: 0 | AW6: 0 | AX6: 0 | AY6: 0 | AZ6: 0 | BA6: 0 | BB6: 0 | BC6: =SUM(AQ6:BB6) -> 0 | BD6: 0 | BE6: 0 | BF6: 0 | BG6: 0 | BH6: 0 | BI6: 0 | BJ6: 0 | BK6: 0 | BL6: 0 | BM6: 0 | BN6: 0 | BO6: 0 | BP6: =SUM(BD6:BO6) -> 0 | BQ6: 0 | BR6: 0 | BS6: 0 | BT6: 0 | BU6: 0 | BV6: 0 | BW6: 0 | BX6: 0 | BY6: 0 | BZ6: 0 | CA6: 0 | CB6: 0 | CC6: =SUM(BQ6:CB6) -> 0 | CD6: =VLOOKUP("Condenação",[2]Saneamento!$A377:$CH419,CD46,0)+VLOOKUP("Penalidades/Irregularidades",[2]Saneamento!$A377:$CH419,CD46,0) -> 0 | CE6: =VLOOKUP("Condenação",[2]Saneamento!$A377:$CH419,CE46,0)+VLOOKUP("Penalidades/Irregularidades",[2]Saneamento!$A377:$CH419,CE46,0) -> 0 | CF6: =VLOOKUP("Condenação",[2]Saneamento!$A377:$CH419,CF46,0)+VLOOKUP("Penalidades/Irregularidades",[2]Saneamento!$A377:$CH419,CF46,0) -> 0 | CG6: =VLOOKUP("Condenação",[2]Saneamento!$A377:$CH419,CG46,0)+VLOOKUP("Penalidades/Irregularidades",[2]Saneamento!$A377:$CH419,CG46,0) -> 0 | CH6: =VLOOKUP("Condenação",[2]Saneamento!$A377:$CH419,CH46,0)+VLOOKUP("Penalidades/Irregularidades",[2]Saneamento!$A377:$CH419,CH46,0) -> 0 | CI6: =VLOOKUP("Condenação",[2]Saneamento!$A377:$CH419,CI46,0)+VLOOKUP("Penalidades/Irregularidades",[2]Saneamento!$A377:$CH419,CI46,0) -> 0 | CJ6: =VLOOKUP("Condenação",[2]Saneamento!$A377:$CH419,CJ46,0)+VLOOKUP("Penalidades/Irregularidades",[2]Saneamento!$A377:$CH419,CJ46,0) -> 0 | CK6: =VLOOKUP("Condenação",[2]Saneamento!$A377:$CH419,CK46,0)+VLOOKUP("Penalidades/Irregularidades",[2]Saneamento!$A377:$CH419,CK46,0) -> 0 | ... CO6: =VLOOKUP("Condenação",[2]Saneamento!$A377:$CH419,CO46,0)+VLOOKUP("Penalidades/Irregularidades",[2]Saneamento!$A377:$CH419,CO46,0) -> 0 | CP6: =SUM(CD6:CO6) -> 0
A7: SANEAMENTO | B7: SANEAMENTO - RESOLUÇÃO DE DISPUTAS | C7: 0 | D7: 0 | E7: 0 | F7: 0 | G7: 0 | H7: 0 | I7: 0 | J7: 0 | K7: 0 | L7: 0 | M7: 0 | N7: 0 | O7: 0 | P7: =SUM(D7:O7) -> 0 | Q7: 0 | R7: 0 | S7: 0 | T7: 0 | U7: 0 | V7: 0 | W7: 0 | X7: 0 | Y7: 0 | Z7: 0 | AA7: 0 | AB7: 0 | AC7: =SUM(Q7:AB7) -> 0 | AD7: 0 | AE7: 0 | AF7: 0 | AG7: 0 | AH7: 0 | AI7: 0 | AJ7: 0 | AK7: 0 | AL7: 0 | AM7: 0 | AN7: 0 | AO7: 0 | AP7: =SUM(AD7:AO7) -> 0 | AQ7: 0 | AR7: 0 | AS7: 0 | AT7: 0 | AU7: 0 | AV7: 0 | AW7: 0 | AX7: 0 | AY7: 0 | AZ7: 0 | BA7: 0 | BB7: 0 | BC7: =SUM(AQ7:BB7) -> 0 | BD7: 0 | BE7: 0 | BF7: 0 | BG7: 0 | BH7: 0 | BI7: 0 | BJ7: 0 | BK7: 0 | BL7: 0 | BM7: 0 | BN7: 0 | BO7: 0 | BP7: =SUM(BD7:BO7) -> 0 | BQ7: 0 | BR7: 0 | BS7: 0 | BT7: 0 | BU7: 0 | BV7: 0 | BW7: 0 | BX7: 0 | BY7: 0 | BZ7: 259.08 | CA7: 0 | CB7: 0 | CC7: =SUM(BQ7:CB7) -> 259.08 | CD7: =VLOOKUP("Condenação",[2]Saneamento!$A129:$CH171,CD46,0)+VLOOKUP("Penalidades/Irregularidades",[2]Saneamento!$A129:$CH171,CD46,0) -> 0 | CE7: =VLOOKUP("Condenação",[2]Saneamento!$A129:$CH171,CE46,0)+VLOOKUP("Penalidades/Irregularidades",[2]Saneamento!$A129:$CH171,CE46,0) -> 0 | CF7: =VLOOKUP("Condenação",[2]Saneamento!$A129:$CH171,CF46,0)+VLOOKUP("Penalidades/Irregularidades",[2]Saneamento!$A129:$CH171,CF46,0) -> 0 | CG7: =VLOOKUP("Condenação",[2]Saneamento!$A129:$CH171,CG46,0)+VLOOKUP("Penalidades/Irregularidades",[2]Saneamento!$A129:$CH171,CG46,0) -> 0 | CH7: =VLOOKUP("Condenação",[2]Saneamento!$A129:$CH171,CH46,0)+VLOOKUP("Penalidades/Irregularidades",[2]Saneamento!$A129:$CH171,CH46,0) -> 0 | CI7: =VLOOKUP("Condenação",[2]Saneamento!$A129:$CH171,CI46,0)+VLOOKUP("Penalidades/Irregularidades",[2]Saneamento!$A129:$CH171,CI46,0) -> 0 | CJ7: =VLOOKUP("Condenação",[2]Saneamento!$A129:$CH171,CJ46,0)+VLOOKUP("Penalidades/Irregularidades",[2]Saneamento!$A129:$CH171,CJ46,0) -> 0 | CK7: =VLOOKUP("Condenação",[2]Saneamento!$A129:$CH171,CK46,0)+VLOOKUP("Penalidades/Irregularidades",[2]Saneamento!$A129:$CH171,CK46,0) -> 0 | ... CO7: =VLOOKUP("Condenação",[2]Saneamento!$A129:$CH171,CO46,0)+VLOOKUP("Penalidades/Irregularidades",[2]Saneamento!$A129:$CH171,CO46,0) -> 0 | CP7: =SUM(CD7:CO7) -> 0
A8: SANEAMENTO | B8: SANEAMENTO - FAB | C8: 0 | D8: 0 | E8: 0 | F8: 0 | G8: 0 | H8: 0 | I8: 0 | J8: 0 | K8: 0 | L8: 0 | M8: 0 | N8: 0 | O8: 0 | P8: =SUM(D8:O8) -> 0 | Q8: 0 | R8: 0 | S8: 0 | T8: 0 | U8: 0 | V8: 0 | W8: 0 | X8: 0 | Y8: 0 | Z8: 0 | AA8: 0 | AB8: 0 | AC8: =SUM(Q8:AB8) -> 0 | AD8: 0 | AE8: 0 | AF8: 0 | AG8: 0 | AH8: 0 | AI8: 0 | AJ8: 0 | AK8: 0 | AL8: 0 | AM8: 0 | AN8: 0 | AO8: 0 | AP8: =SUM(AD8:AO8) -> 0 | AQ8: 0 | AR8: 0 | AS8: 0 | AT8: 0 | AU8: 0 | AV8: 0 | AW8: 0 | AX8: 0 | AY8: 0 | AZ8: 0 | BA8: 0 | BB8: 0 | BC8: =SUM(AQ8:BB8) -> 0 | BD8: 0 | BE8: 0 | BF8: 0 | BG8: 0 | BH8: 0 | BI8: 0 | BJ8: 0 | BK8: 0 | BL8: 0 | BM8: 0 | BN8: 0 | BO8: 0 | BP8: =SUM(BD8:BO8) -> 0 | BQ8: 0 | BR8: 0 | BS8: 0 | BT8: 0 | BU8: 0 | BV8: 0 | BW8: 0 | BX8: 0 | BY8: 0 | BZ8: 0 | CA8: 0 | CB8: 0 | CC8: =SUM(BQ8:CB8) -> 0 | CD8: =VLOOKUP("Condenação",[2]Saneamento!$A253:$CH295,CD46,0)+VLOOKUP("Penalidades/Irregularidades",[2]Saneamento!$A253:$CH295,CD46,0) -> 0 | CE8: =VLOOKUP("Condenação",[2]Saneamento!$A253:$CH295,CE46,0)+VLOOKUP("Penalidades/Irregularidades",[2]Saneamento!$A253:$CH295,CE46,0) -> 0 | CF8: =VLOOKUP("Condenação",[2]Saneamento!$A253:$CH295,CF46,0)+VLOOKUP("Penalidades/Irregularidades",[2]Saneamento!$A253:$CH295,CF46,0) -> 0 | CG8: =VLOOKUP("Condenação",[2]Saneamento!$A253:$CH295,CG46,0)+VLOOKUP("Penalidades/Irregularidades",[2]Saneamento!$A253:$CH295,CG46,0) -> 0 | CH8: =VLOOKUP("Condenação",[2]Saneamento!$A253:$CH295,CH46,0)+VLOOKUP("Penalidades/Irregularidades",[2]Saneamento!$A253:$CH295,CH46,0) -> 0 | CI8: =VLOOKUP("Condenação",[2]Saneamento!$A253:$CH295,CI46,0)+VLOOKUP("Penalidades/Irregularidades",[2]Saneamento!$A253:$CH295,CI46,0) -> 0 | CJ8: =VLOOKUP("Condenação",[2]Saneamento!$A253:$CH295,CJ46,0)+VLOOKUP("Penalidades/Irregularidades",[2]Saneamento!$A253:$CH295,CJ46,0) -> 0 | CK8: =VLOOKUP("Condenação",[2]Saneamento!$A253:$CH295,CK46,0)+VLOOKUP("Penalidades/Irregularidades",[2]Saneamento!$A253:$CH295,CK46,0) -> 0 | ... CO8: =VLOOKUP("Condenação",[2]Saneamento!$A253:$CH295,CO46,0)+VLOOKUP("Penalidades/Irregularidades",[2]Saneamento!$A253:$CH295,CO46,0) -> 0 | CP8: =SUM(CD8:CO8) -> 0
